----- OS TEST 0 ----------------------------------------------------
./os os_0
Time slot   0
	Loaded a process at input/proc/p0, PID: 1
Time slot   1
	CPU 0: Dispatched process  1
	Loaded a process at input/proc/p1, PID: 2
Time slot   2
	CPU 1: Dispatched process  2
Time slot   3
	Loaded a process at input/proc/p1, PID: 3
Time slot   4
	Loaded a process at input/proc/p1, PID: 4
Time slot   5
Time slot   6
Time slot   7
	CPU 0: Put process  1 to run queue
	CPU 0: Dispatched process  3
Time slot   8
	CPU 1: Put process  2 to run queue
	CPU 1: Dispatched process  4
Time slot   9
Time slot  10
Time slot  11
Time slot  12
Time slot  13
	CPU 0: Put process  3 to run queue
	CPU 0: Dispatched process  1
Time slot  14
	CPU 1: Put process  4 to run queue
	CPU 1: Dispatched process  2
Time slot  15
Time slot  16
Time slot  17
	CPU 0: Processed  1 has finished
	CPU 0: Dispatched process  3
Time slot  18
	CPU 1: Processed  2 has finished
	CPU 1: Dispatched process  4
Time slot  19
Time slot  20
Time slot  21
	CPU 0: Processed  3 has finished
	CPU 0 stopped
Time slot  22
	CPU 1: Processed  4 has finished
	CPU 1 stopped

MEMORY CONTENT:
000: 00000-003ff - PID: 01 (idx 000, nxt: -01)
	00014: 64
001: 00400-007ff - PID: 03 (idx 000, nxt: 007)
002: 00800-00bff - PID: 02 (idx 000, nxt: 003)
003: 00c00-00fff - PID: 02 (idx 001, nxt: 004)
004: 01000-013ff - PID: 02 (idx 002, nxt: 005)
	011e7: 0a
005: 01400-017ff - PID: 02 (idx 003, nxt: 006)
006: 01800-01bff - PID: 02 (idx 004, nxt: -01)
007: 01c00-01fff - PID: 03 (idx 001, nxt: 008)
008: 02000-023ff - PID: 03 (idx 002, nxt: 009)
009: 02400-027ff - PID: 03 (idx 003, nxt: -01)
010: 02800-02bff - PID: 04 (idx 000, nxt: 011)
011: 02c00-02fff - PID: 04 (idx 001, nxt: 012)
012: 03000-033ff - PID: 04 (idx 002, nxt: 013)
013: 03400-037ff - PID: 04 (idx 003, nxt: -01)
015: 03c00-03fff - PID: 03 (idx 000, nxt: 016)
016: 04000-043ff - PID: 03 (idx 001, nxt: 017)
017: 04400-047ff - PID: 03 (idx 002, nxt: 018)
	045e7: 0a
018: 04800-04bff - PID: 03 (idx 003, nxt: 019)
019: 04c00-04fff - PID: 03 (idx 004, nxt: -01)
020: 05000-053ff - PID: 04 (idx 000, nxt: 021)
021: 05400-057ff - PID: 04 (idx 001, nxt: 022)
022: 05800-05bff - PID: 04 (idx 002, nxt: 023)
	059e7: 0a
023: 05c00-05fff - PID: 04 (idx 003, nxt: 024)
024: 06000-063ff - PID: 04 (idx 004, nxt: -01)
033: 08400-087ff - PID: 02 (idx 000, nxt: 034)
034: 08800-08bff - PID: 02 (idx 001, nxt: 035)
035: 08c00-08fff - PID: 02 (idx 002, nxt: 036)
036: 09000-093ff - PID: 02 (idx 003, nxt: -01)
NOTE: Read file output/os_0 to verify your result
----- OS TEST 1 ----------------------------------------------------
./os os_1
Time slot   0
	Loaded a process at input/proc/p0, PID: 1
Time slot   1
	CPU 1: Dispatched process  1
Time slot   2
	Loaded a process at input/proc/s3, PID: 2
	CPU 0: Dispatched process  2
Time slot   3
	CPU 1: Put process  1 to run queue
	CPU 1: Dispatched process  1
	Loaded a process at input/proc/m1, PID: 3
Time slot   4
	CPU 0: Put process  2 to run queue
	CPU 0: Dispatched process  3
	CPU 2: Dispatched process  2
Time slot   5
	CPU 1: Put process  1 to run queue
	CPU 1: Dispatched process  1
	Loaded a process at input/proc/s2, PID: 4
	CPU 3: Dispatched process  4
Time slot   6
	CPU 0: Put process  3 to run queue
	CPU 0: Dispatched process  3
	CPU 2: Put process  2 to run queue
	CPU 2: Dispatched process  2
Time slot   7
	CPU 1: Put process  1 to run queue
	CPU 1: Dispatched process  1
	Loaded a process at input/proc/m0, PID: 5
	CPU 3: Put process  4 to run queue
	CPU 3: Dispatched process  5
Time slot   8
	CPU 0: Put process  3 to run queue
	CPU 0: Dispatched process  3
	CPU 2: Put process  2 to run queue
	CPU 2: Dispatched process  4
	Loaded a process at input/proc/p1, PID: 6
Time slot   9
	CPU 1: Put process  1 to run queue
	CPU 1: Dispatched process  6
	CPU 3: Put process  5 to run queue
	CPU 3: Dispatched process  1
Time slot  10
	CPU 0: Put process  3 to run queue
	CPU 0: Dispatched process  5
	CPU 2: Put process  4 to run queue
	CPU 2: Dispatched process  2
	Loaded a process at input/proc/s0, PID: 7
Time slot  11
	CPU 1: Put process  6 to run queue
	CPU 1: Dispatched process  7
	CPU 3: Processed  1 has finished
	CPU 3: Dispatched process  3
Time slot  12
	CPU 0: Put process  5 to run queue
	CPU 0: Dispatched process  6
	CPU 2: Put process  2 to run queue
	CPU 2: Dispatched process  4
Time slot  13
	CPU 1: Put process  7 to run queue
	CPU 1: Dispatched process  5
	CPU 3: Processed  3 has finished
	CPU 3: Dispatched process  2
Time slot  14
	CPU 0: Put process  6 to run queue
	CPU 0: Dispatched process  7
	CPU 2: Put process  4 to run queue
	CPU 2: Dispatched process  6
Time slot  15
	CPU 1: Put process  5 to run queue
	CPU 1: Dispatched process  4
	Loaded a process at input/proc/s1, PID: 8
	CPU 3: Put process  2 to run queue
	CPU 3: Dispatched process  8
Time slot  16
	CPU 0: Put process  7 to run queue
	CPU 0: Dispatched process  5
	CPU 2: Put process  6 to run queue
	CPU 2: Dispatched process  2
Time slot  17
	CPU 0: Processed  5 has finished
	CPU 0: Dispatched process  7
	CPU 1: Put process  4 to run queue
	CPU 1: Dispatched process  6
	CPU 2: Processed  2 has finished
	CPU 2: Dispatched process  4
	CPU 3: Put process  8 to run queue
	CPU 3: Dispatched process  8
Time slot  18
Time slot  19
	CPU 0: Put process  7 to run queue
	CPU 0: Dispatched process  7
	CPU 1: Put process  6 to run queue
	CPU 1: Dispatched process  6
	CPU 2: Put process  4 to run queue
	CPU 2: Dispatched process  4
	CPU 3: Put process  8 to run queue
	CPU 3: Dispatched process  8
Time slot  20
Time slot  21
	CPU 0: Put process  7 to run queue
	CPU 0: Dispatched process  7
	CPU 1: Processed  6 has finished
	CPU 1 stopped
	CPU 2: Processed  4 has finished
	CPU 2 stopped
Time slot  22
	CPU 3: Put process  8 to run queue
	CPU 3: Dispatched process  8
	CPU 3: Processed  8 has finished
Time slot  23
	CPU 3 stopped
	CPU 0: Put process  7 to run queue
	CPU 0: Dispatched process  7
Time slot  24
Time slot  25
	CPU 0: Put process  7 to run queue
	CPU 0: Dispatched process  7
Time slot  26
Time slot  27
	CPU 0: Put process  7 to run queue
	CPU 0: Dispatched process  7
Time slot  28
	CPU 0: Processed  7 has finished
	CPU 0 stopped

MEMORY CONTENT:
000: 00000-003ff - PID: 05 (idx 000, nxt: 001)
001: 00400-007ff - PID: 05 (idx 001, nxt: 004)
002: 00800-00bff - PID: 05 (idx 000, nxt: 003)
	00be8: 15
003: 00c00-00fff - PID: 05 (idx 001, nxt: -01)
004: 01000-013ff - PID: 05 (idx 002, nxt: 005)
005: 01400-017ff - PID: 05 (idx 003, nxt: 006)
006: 01800-01bff - PID: 05 (idx 004, nxt: -01)
007: 01c00-01fff - PID: 06 (idx 000, nxt: 008)
008: 02000-023ff - PID: 06 (idx 001, nxt: 009)
009: 02400-027ff - PID: 06 (idx 002, nxt: 010)
	025e7: 0a
010: 02800-02bff - PID: 06 (idx 003, nxt: 011)
011: 02c00-02fff - PID: 06 (idx 004, nxt: -01)
016: 04000-043ff - PID: 06 (idx 000, nxt: 017)
017: 04400-047ff - PID: 06 (idx 001, nxt: 018)
018: 04800-04bff - PID: 06 (idx 002, nxt: 019)
019: 04c00-04fff - PID: 06 (idx 003, nxt: -01)
021: 05400-057ff - PID: 01 (idx 000, nxt: -01)
	05414: 64
029: 07400-077ff - PID: 05 (idx 000, nxt: 030)
	07414: 66
030: 07800-07bff - PID: 05 (idx 001, nxt: -01)
NOTE: Read file output/os_1 to verify your result
